NAMESPACE   LAST SEEN   TYPE      REASON                 OBJECT                                MESSAGE
default     13m         Normal    NodeNotReady           node/e1                               Node e1 status is now: NodeNotReady
default     13m         Normal    NodeNotReady           node/e2                               Node e2 status is now: NodeNotReady
kubeedge    13m         Warning   NodeNotReady           pod/edge-eclipse-mosquitto-7l5gz      Node is not ready
kubeedge    13m         Warning   NodeNotReady           pod/edge-eclipse-mosquitto-szthb      Node is not ready
kubeedge    13m         Warning   NodeNotReady           pod/edgemesh-agent-l2n4z              Node is not ready
kubeedge    13m         Warning   NodeNotReady           pod/edgemesh-agent-qf7pk              Node is not ready
testapp     60m         Warning   FailedScheduling       pod/nginx-testapp-5c8f4cb9d7-wvqk9    0/5 nodes are available: 2 node(s) had untolerated taint(s), 3 node(s) didn't match Pod's node affinity/selector. no new claims to deallocate, preemption: 0/5 nodes are available: 5 Preemption is not helpful for scheduling.
testapp     60m         Normal    TaintManagerEviction   pod/nginx-testapp-5c8f4cb9d7-w2rxw    Marking for deletion Pod testapp/nginx-testapp-5c8f4cb9d7-w2rxw
testapp     60m         Normal    SuccessfulCreate       replicaset/nginx-testapp-5c8f4cb9d7   Created pod: nginx-testapp-5c8f4cb9d7-qpq6v
testapp     60m         Warning   FailedScheduling       pod/nginx-testapp-5c8f4cb9d7-v9twn    0/5 nodes are available: 2 node(s) had untolerated taint(s), 3 node(s) didn't match Pod's node affinity/selector. no new claims to deallocate, preemption: 0/5 nodes are available: 5 Preemption is not helpful for scheduling.
testapp     60m         Normal    SuccessfulCreate       replicaset/nginx-testapp-5c8f4cb9d7   Created pod: nginx-testapp-5c8f4cb9d7-wvqk9
testapp     60m         Normal    SuccessfulCreate       replicaset/nginx-testapp-5c8f4cb9d7   Created pod: nginx-testapp-5c8f4cb9d7-v9twn
testapp     60m         Normal    TaintManagerEviction   pod/nginx-testapp-5c8f4cb9d7-g5cmz    Marking for deletion Pod testapp/nginx-testapp-5c8f4cb9d7-g5cmz
testapp     60m         Warning   FailedScheduling       pod/nginx-testapp-5c8f4cb9d7-qpq6v    0/5 nodes are available: 2 node(s) had untolerated taint(s), 3 node(s) didn't match Pod's node affinity/selector. no new claims to deallocate, preemption: 0/5 nodes are available: 5 Preemption is not helpful for scheduling.
testapp     60m         Normal    TaintManagerEviction   pod/nginx-testapp-5c8f4cb9d7-l5vdm    Marking for deletion Pod testapp/nginx-testapp-5c8f4cb9d7-l5vdm
testapp     55m         Normal    Scheduled              pod/nginx-testapp-5c8f4cb9d7-v9twn    Successfully assigned testapp/nginx-testapp-5c8f4cb9d7-v9twn to e2
testapp     55m         Normal    Scheduled              pod/nginx-testapp-5c8f4cb9d7-wvqk9    Successfully assigned testapp/nginx-testapp-5c8f4cb9d7-wvqk9 to e2
testapp     55m         Normal    Scheduled              pod/nginx-testapp-5c8f4cb9d7-qpq6v    Successfully assigned testapp/nginx-testapp-5c8f4cb9d7-qpq6v to e2
testapp     55m         Normal    TaintManagerEviction   pod/nginx-testapp-5c8f4cb9d7-wvqk9    Cancelling deletion of Pod testapp/nginx-testapp-5c8f4cb9d7-wvqk9
testapp     55m         Normal    TaintManagerEviction   pod/nginx-testapp-5c8f4cb9d7-qpq6v    Cancelling deletion of Pod testapp/nginx-testapp-5c8f4cb9d7-qpq6v
testapp     55m         Normal    TaintManagerEviction   pod/nginx-testapp-5c8f4cb9d7-v9twn    Cancelling deletion of Pod testapp/nginx-testapp-5c8f4cb9d7-v9twn
testapp     47m         Warning   NodeNotReady           pod/nginx-testapp-5c8f4cb9d7-v9twn    Node is not ready
testapp     47m         Warning   NodeNotReady           pod/nginx-testapp-5c8f4cb9d7-qpq6v    Node is not ready
testapp     47m         Warning   NodeNotReady           pod/nginx-testapp-5c8f4cb9d7-wvqk9    Node is not ready
testapp     42m         Normal    SuccessfulCreate       replicaset/nginx-testapp-5c8f4cb9d7   Created pod: nginx-testapp-5c8f4cb9d7-6fcx6
testapp     42m         Normal    TaintManagerEviction   pod/nginx-testapp-5c8f4cb9d7-v9twn    Marking for deletion Pod testapp/nginx-testapp-5c8f4cb9d7-v9twn
testapp     42m         Normal    TaintManagerEviction   pod/nginx-testapp-5c8f4cb9d7-wvqk9    Marking for deletion Pod testapp/nginx-testapp-5c8f4cb9d7-wvqk9
testapp     42m         Warning   FailedScheduling       pod/nginx-testapp-5c8f4cb9d7-z8c67    0/5 nodes are available: 2 node(s) had untolerated taint(s), 3 node(s) didn't match Pod's node affinity/selector. no new claims to deallocate, preemption: 0/5 nodes are available: 5 Preemption is not helpful for scheduling.
testapp     42m         Normal    SuccessfulCreate       replicaset/nginx-testapp-5c8f4cb9d7   Created pod: nginx-testapp-5c8f4cb9d7-bdwht
testapp     42m         Warning   FailedScheduling       pod/nginx-testapp-5c8f4cb9d7-6fcx6    0/5 nodes are available: 2 node(s) had untolerated taint(s), 3 node(s) didn't match Pod's node affinity/selector. no new claims to deallocate, preemption: 0/5 nodes are available: 5 Preemption is not helpful for scheduling.
testapp     42m         Normal    SuccessfulCreate       replicaset/nginx-testapp-5c8f4cb9d7   Created pod: nginx-testapp-5c8f4cb9d7-z8c67
testapp     42m         Normal    TaintManagerEviction   pod/nginx-testapp-5c8f4cb9d7-qpq6v    Marking for deletion Pod testapp/nginx-testapp-5c8f4cb9d7-qpq6v
testapp     42m         Warning   FailedScheduling       pod/nginx-testapp-5c8f4cb9d7-bdwht    0/5 nodes are available: 2 node(s) had untolerated taint(s), 3 node(s) didn't match Pod's node affinity/selector. no new claims to deallocate, preemption: 0/5 nodes are available: 5 Preemption is not helpful for scheduling.
testapp     38m         Normal    Scheduled              pod/nginx-testapp-5c8f4cb9d7-bdwht    Successfully assigned testapp/nginx-testapp-5c8f4cb9d7-bdwht to e2
testapp     38m         Normal    Scheduled              pod/nginx-testapp-5c8f4cb9d7-6fcx6    Successfully assigned testapp/nginx-testapp-5c8f4cb9d7-6fcx6 to e2
testapp     38m         Normal    Scheduled              pod/nginx-testapp-5c8f4cb9d7-z8c67    Successfully assigned testapp/nginx-testapp-5c8f4cb9d7-z8c67 to e2
testapp     38m         Normal    TaintManagerEviction   pod/nginx-testapp-5c8f4cb9d7-bdwht    Cancelling deletion of Pod testapp/nginx-testapp-5c8f4cb9d7-bdwht
testapp     38m         Normal    TaintManagerEviction   pod/nginx-testapp-5c8f4cb9d7-6fcx6    Cancelling deletion of Pod testapp/nginx-testapp-5c8f4cb9d7-6fcx6
testapp     38m         Normal    TaintManagerEviction   pod/nginx-testapp-5c8f4cb9d7-z8c67    Cancelling deletion of Pod testapp/nginx-testapp-5c8f4cb9d7-z8c67
testapp     30m         Warning   NodeNotReady           pod/nginx-testapp-5c8f4cb9d7-6fcx6    Node is not ready
testapp     30m         Warning   NodeNotReady           pod/nginx-testapp-5c8f4cb9d7-bdwht    Node is not ready
testapp     30m         Warning   NodeNotReady           pod/nginx-testapp-5c8f4cb9d7-z8c67    Node is not ready
testapp     25m         Normal    SuccessfulCreate       replicaset/nginx-testapp-5c8f4cb9d7   Created pod: nginx-testapp-5c8f4cb9d7-22f2p
testapp     25m         Warning   FailedScheduling       pod/nginx-testapp-5c8f4cb9d7-sr2tl    0/5 nodes are available: 2 node(s) had untolerated taint(s), 3 node(s) didn't match Pod's node affinity/selector. no new claims to deallocate, preemption: 0/5 nodes are available: 5 Preemption is not helpful for scheduling.
testapp     25m         Normal    TaintManagerEviction   pod/nginx-testapp-5c8f4cb9d7-6fcx6    Marking for deletion Pod testapp/nginx-testapp-5c8f4cb9d7-6fcx6
testapp     25m         Warning   FailedScheduling       pod/nginx-testapp-5c8f4cb9d7-f5lv5    0/5 nodes are available: 2 node(s) had untolerated taint(s), 3 node(s) didn't match Pod's node affinity/selector. no new claims to deallocate, preemption: 0/5 nodes are available: 5 Preemption is not helpful for scheduling.
testapp     25m         Normal    TaintManagerEviction   pod/nginx-testapp-5c8f4cb9d7-bdwht    Marking for deletion Pod testapp/nginx-testapp-5c8f4cb9d7-bdwht
testapp     25m         Normal    SuccessfulCreate       replicaset/nginx-testapp-5c8f4cb9d7   Created pod: nginx-testapp-5c8f4cb9d7-f5lv5
testapp     25m         Normal    TaintManagerEviction   pod/nginx-testapp-5c8f4cb9d7-z8c67    Marking for deletion Pod testapp/nginx-testapp-5c8f4cb9d7-z8c67
testapp     25m         Normal    SuccessfulCreate       replicaset/nginx-testapp-5c8f4cb9d7   Created pod: nginx-testapp-5c8f4cb9d7-sr2tl
testapp     25m         Warning   FailedScheduling       pod/nginx-testapp-5c8f4cb9d7-22f2p    0/5 nodes are available: 2 node(s) had untolerated taint(s), 3 node(s) didn't match Pod's node affinity/selector. no new claims to deallocate, preemption: 0/5 nodes are available: 5 Preemption is not helpful for scheduling.
testapp     21m         Normal    Scheduled              pod/nginx-testapp-5c8f4cb9d7-sr2tl    Successfully assigned testapp/nginx-testapp-5c8f4cb9d7-sr2tl to e1
testapp     21m         Normal    Scheduled              pod/nginx-testapp-5c8f4cb9d7-f5lv5    Successfully assigned testapp/nginx-testapp-5c8f4cb9d7-f5lv5 to e1
testapp     21m         Normal    Scheduled              pod/nginx-testapp-5c8f4cb9d7-22f2p    Successfully assigned testapp/nginx-testapp-5c8f4cb9d7-22f2p to e1
testapp     21m         Normal    TaintManagerEviction   pod/nginx-testapp-5c8f4cb9d7-22f2p    Cancelling deletion of Pod testapp/nginx-testapp-5c8f4cb9d7-22f2p
testapp     21m         Normal    TaintManagerEviction   pod/nginx-testapp-5c8f4cb9d7-sr2tl    Cancelling deletion of Pod testapp/nginx-testapp-5c8f4cb9d7-sr2tl
testapp     21m         Normal    TaintManagerEviction   pod/nginx-testapp-5c8f4cb9d7-f5lv5    Cancelling deletion of Pod testapp/nginx-testapp-5c8f4cb9d7-f5lv5
testapp     13m         Warning   NodeNotReady           pod/nginx-testapp-5c8f4cb9d7-22f2p    Node is not ready
testapp     13m         Warning   NodeNotReady           pod/nginx-testapp-5c8f4cb9d7-sr2tl    Node is not ready
testapp     13m         Warning   NodeNotReady           pod/nginx-testapp-5c8f4cb9d7-f5lv5    Node is not ready
testapp     8m15s       Warning   FailedScheduling       pod/nginx-testapp-5c8f4cb9d7-r2ncq    0/5 nodes are available: 2 node(s) had untolerated taint(s), 3 node(s) didn't match Pod's node affinity/selector. no new claims to deallocate, preemption: 0/5 nodes are available: 5 Preemption is not helpful for scheduling.
testapp     8m16s       Normal    TaintManagerEviction   pod/nginx-testapp-5c8f4cb9d7-f5lv5    Marking for deletion Pod testapp/nginx-testapp-5c8f4cb9d7-f5lv5
testapp     8m16s       Normal    SuccessfulCreate       replicaset/nginx-testapp-5c8f4cb9d7   Created pod: nginx-testapp-5c8f4cb9d7-6fs8g
testapp     8m15s       Warning   FailedScheduling       pod/nginx-testapp-5c8f4cb9d7-vqmnl    0/5 nodes are available: 2 node(s) had untolerated taint(s), 3 node(s) didn't match Pod's node affinity/selector. no new claims to deallocate, preemption: 0/5 nodes are available: 5 Preemption is not helpful for scheduling.
testapp     8m16s       Normal    TaintManagerEviction   pod/nginx-testapp-5c8f4cb9d7-sr2tl    Marking for deletion Pod testapp/nginx-testapp-5c8f4cb9d7-sr2tl
testapp     8m16s       Normal    SuccessfulCreate       replicaset/nginx-testapp-5c8f4cb9d7   Created pod: nginx-testapp-5c8f4cb9d7-vqmnl
testapp     8m16s       Normal    SuccessfulCreate       replicaset/nginx-testapp-5c8f4cb9d7   Created pod: nginx-testapp-5c8f4cb9d7-r2ncq
testapp     8m16s       Normal    TaintManagerEviction   pod/nginx-testapp-5c8f4cb9d7-22f2p    Marking for deletion Pod testapp/nginx-testapp-5c8f4cb9d7-22f2p
testapp     8m15s       Warning   FailedScheduling       pod/nginx-testapp-5c8f4cb9d7-6fs8g    0/5 nodes are available: 2 node(s) had untolerated taint(s), 3 node(s) didn't match Pod's node affinity/selector. no new claims to deallocate, preemption: 0/5 nodes are available: 5 Preemption is not helpful for scheduling.
testapp     3m57s       Normal    Scheduled              pod/nginx-testapp-5c8f4cb9d7-6fs8g    Successfully assigned testapp/nginx-testapp-5c8f4cb9d7-6fs8g to e2
testapp     3m57s       Normal    Scheduled              pod/nginx-testapp-5c8f4cb9d7-r2ncq    Successfully assigned testapp/nginx-testapp-5c8f4cb9d7-r2ncq to e2
testapp     3m57s       Normal    Scheduled              pod/nginx-testapp-5c8f4cb9d7-vqmnl    Successfully assigned testapp/nginx-testapp-5c8f4cb9d7-vqmnl to e2
testapp     3m56s       Normal    TaintManagerEviction   pod/nginx-testapp-5c8f4cb9d7-6fs8g    Cancelling deletion of Pod testapp/nginx-testapp-5c8f4cb9d7-6fs8g
testapp     3m56s       Normal    TaintManagerEviction   pod/nginx-testapp-5c8f4cb9d7-vqmnl    Cancelling deletion of Pod testapp/nginx-testapp-5c8f4cb9d7-vqmnl
testapp     3m56s       Normal    TaintManagerEviction   pod/nginx-testapp-5c8f4cb9d7-r2ncq    Cancelling deletion of Pod testapp/nginx-testapp-5c8f4cb9d7-r2ncq
