NAMESPACE   LAST SEEN   TYPE      REASON                 OBJECT                                MESSAGE
default     115s        Normal    NodeNotReady           node/e1                               Node e1 status is now: NodeNotReady
default     12m         Normal    NodeNotReady           node/e2                               Node e2 status is now: NodeNotReady
kubeedge    12m         Warning   NodeNotReady           pod/edge-eclipse-mosquitto-7l5gz      Node is not ready
kubeedge    12m         Warning   NodeNotReady           pod/edge-eclipse-mosquitto-szthb      Node is not ready
kubeedge    12m         Warning   NodeNotReady           pod/edgemesh-agent-l2n4z              Node is not ready
kubeedge    12m         Warning   NodeNotReady           pod/edgemesh-agent-qf7pk              Node is not ready
testapp     58m         Warning   FailedScheduling       pod/nginx-testapp-5c8f4cb9d7-6fs8g    0/5 nodes are available: 2 node(s) had untolerated taint(s), 3 node(s) didn't match Pod's node affinity/selector. no new claims to deallocate, preemption: 0/5 nodes are available: 5 Preemption is not helpful for scheduling.
testapp     58m         Normal    TaintManagerEviction   pod/nginx-testapp-5c8f4cb9d7-sr2tl    Marking for deletion Pod testapp/nginx-testapp-5c8f4cb9d7-sr2tl
testapp     58m         Normal    SuccessfulCreate       replicaset/nginx-testapp-5c8f4cb9d7   Created pod: nginx-testapp-5c8f4cb9d7-vqmnl
testapp     58m         Normal    SuccessfulCreate       replicaset/nginx-testapp-5c8f4cb9d7   Created pod: nginx-testapp-5c8f4cb9d7-r2ncq
testapp     58m         Normal    SuccessfulCreate       replicaset/nginx-testapp-5c8f4cb9d7   Created pod: nginx-testapp-5c8f4cb9d7-6fs8g
testapp     58m         Warning   FailedScheduling       pod/nginx-testapp-5c8f4cb9d7-r2ncq    0/5 nodes are available: 2 node(s) had untolerated taint(s), 3 node(s) didn't match Pod's node affinity/selector. no new claims to deallocate, preemption: 0/5 nodes are available: 5 Preemption is not helpful for scheduling.
testapp     58m         Normal    TaintManagerEviction   pod/nginx-testapp-5c8f4cb9d7-f5lv5    Marking for deletion Pod testapp/nginx-testapp-5c8f4cb9d7-f5lv5
testapp     58m         Normal    TaintManagerEviction   pod/nginx-testapp-5c8f4cb9d7-22f2p    Marking for deletion Pod testapp/nginx-testapp-5c8f4cb9d7-22f2p
testapp     58m         Warning   FailedScheduling       pod/nginx-testapp-5c8f4cb9d7-vqmnl    0/5 nodes are available: 2 node(s) had untolerated taint(s), 3 node(s) didn't match Pod's node affinity/selector. no new claims to deallocate, preemption: 0/5 nodes are available: 5 Preemption is not helpful for scheduling.
testapp     54m         Normal    Scheduled              pod/nginx-testapp-5c8f4cb9d7-r2ncq    Successfully assigned testapp/nginx-testapp-5c8f4cb9d7-r2ncq to e2
testapp     54m         Normal    Scheduled              pod/nginx-testapp-5c8f4cb9d7-6fs8g    Successfully assigned testapp/nginx-testapp-5c8f4cb9d7-6fs8g to e2
testapp     54m         Normal    Scheduled              pod/nginx-testapp-5c8f4cb9d7-vqmnl    Successfully assigned testapp/nginx-testapp-5c8f4cb9d7-vqmnl to e2
testapp     54m         Normal    TaintManagerEviction   pod/nginx-testapp-5c8f4cb9d7-vqmnl    Cancelling deletion of Pod testapp/nginx-testapp-5c8f4cb9d7-vqmnl
testapp     54m         Normal    TaintManagerEviction   pod/nginx-testapp-5c8f4cb9d7-6fs8g    Cancelling deletion of Pod testapp/nginx-testapp-5c8f4cb9d7-6fs8g
testapp     54m         Normal    TaintManagerEviction   pod/nginx-testapp-5c8f4cb9d7-r2ncq    Cancelling deletion of Pod testapp/nginx-testapp-5c8f4cb9d7-r2ncq
testapp     46m         Warning   NodeNotReady           pod/nginx-testapp-5c8f4cb9d7-6fs8g    Node is not ready
testapp     46m         Warning   NodeNotReady           pod/nginx-testapp-5c8f4cb9d7-r2ncq    Node is not ready
testapp     46m         Warning   NodeNotReady           pod/nginx-testapp-5c8f4cb9d7-vqmnl    Node is not ready
testapp     41m         Normal    TaintManagerEviction   pod/nginx-testapp-5c8f4cb9d7-r2ncq    Marking for deletion Pod testapp/nginx-testapp-5c8f4cb9d7-r2ncq
testapp     41m         Warning   FailedScheduling       pod/nginx-testapp-5c8f4cb9d7-rdtgx    0/5 nodes are available: 2 node(s) had untolerated taint(s), 3 node(s) didn't match Pod's node affinity/selector. no new claims to deallocate, preemption: 0/5 nodes are available: 5 Preemption is not helpful for scheduling.
testapp     41m         Normal    TaintManagerEviction   pod/nginx-testapp-5c8f4cb9d7-vqmnl    Marking for deletion Pod testapp/nginx-testapp-5c8f4cb9d7-vqmnl
testapp     41m         Warning   FailedScheduling       pod/nginx-testapp-5c8f4cb9d7-rpw24    0/5 nodes are available: 2 node(s) had untolerated taint(s), 3 node(s) didn't match Pod's node affinity/selector. no new claims to deallocate, preemption: 0/5 nodes are available: 5 Preemption is not helpful for scheduling.
testapp     41m         Normal    TaintManagerEviction   pod/nginx-testapp-5c8f4cb9d7-6fs8g    Marking for deletion Pod testapp/nginx-testapp-5c8f4cb9d7-6fs8g
testapp     41m         Warning   FailedScheduling       pod/nginx-testapp-5c8f4cb9d7-4pl6l    0/5 nodes are available: 2 node(s) had untolerated taint(s), 3 node(s) didn't match Pod's node affinity/selector. no new claims to deallocate, preemption: 0/5 nodes are available: 5 Preemption is not helpful for scheduling.
testapp     41m         Normal    SuccessfulCreate       replicaset/nginx-testapp-5c8f4cb9d7   Created pod: nginx-testapp-5c8f4cb9d7-4pl6l
testapp     41m         Normal    SuccessfulCreate       replicaset/nginx-testapp-5c8f4cb9d7   Created pod: nginx-testapp-5c8f4cb9d7-rpw24
testapp     41m         Normal    SuccessfulCreate       replicaset/nginx-testapp-5c8f4cb9d7   Created pod: nginx-testapp-5c8f4cb9d7-rdtgx
testapp     36m         Normal    Scheduled              pod/nginx-testapp-5c8f4cb9d7-rpw24    Successfully assigned testapp/nginx-testapp-5c8f4cb9d7-rpw24 to e2
testapp     36m         Normal    Scheduled              pod/nginx-testapp-5c8f4cb9d7-4pl6l    Successfully assigned testapp/nginx-testapp-5c8f4cb9d7-4pl6l to e2
testapp     36m         Normal    Scheduled              pod/nginx-testapp-5c8f4cb9d7-rdtgx    Successfully assigned testapp/nginx-testapp-5c8f4cb9d7-rdtgx to e2
testapp     36m         Normal    TaintManagerEviction   pod/nginx-testapp-5c8f4cb9d7-4pl6l    Cancelling deletion of Pod testapp/nginx-testapp-5c8f4cb9d7-4pl6l
testapp     36m         Normal    TaintManagerEviction   pod/nginx-testapp-5c8f4cb9d7-rdtgx    Cancelling deletion of Pod testapp/nginx-testapp-5c8f4cb9d7-rdtgx
testapp     36m         Normal    TaintManagerEviction   pod/nginx-testapp-5c8f4cb9d7-rpw24    Cancelling deletion of Pod testapp/nginx-testapp-5c8f4cb9d7-rpw24
testapp     29m         Warning   NodeNotReady           pod/nginx-testapp-5c8f4cb9d7-4pl6l    Node is not ready
testapp     29m         Warning   NodeNotReady           pod/nginx-testapp-5c8f4cb9d7-rpw24    Node is not ready
testapp     29m         Warning   NodeNotReady           pod/nginx-testapp-5c8f4cb9d7-rdtgx    Node is not ready
testapp     24m         Normal    SuccessfulCreate       replicaset/nginx-testapp-5c8f4cb9d7   Created pod: nginx-testapp-5c8f4cb9d7-m5z9f
testapp     24m         Warning   FailedScheduling       pod/nginx-testapp-5c8f4cb9d7-m5z9f    0/5 nodes are available: 2 node(s) had untolerated taint(s), 3 node(s) didn't match Pod's node affinity/selector. no new claims to deallocate, preemption: 0/5 nodes are available: 5 Preemption is not helpful for scheduling.
testapp     24m         Normal    TaintManagerEviction   pod/nginx-testapp-5c8f4cb9d7-rdtgx    Marking for deletion Pod testapp/nginx-testapp-5c8f4cb9d7-rdtgx
testapp     24m         Normal    SuccessfulCreate       replicaset/nginx-testapp-5c8f4cb9d7   Created pod: nginx-testapp-5c8f4cb9d7-vjwx2
testapp     24m         Normal    TaintManagerEviction   pod/nginx-testapp-5c8f4cb9d7-rpw24    Marking for deletion Pod testapp/nginx-testapp-5c8f4cb9d7-rpw24
testapp     24m         Normal    SuccessfulCreate       replicaset/nginx-testapp-5c8f4cb9d7   Created pod: nginx-testapp-5c8f4cb9d7-wjb6p
testapp     24m         Warning   FailedScheduling       pod/nginx-testapp-5c8f4cb9d7-vjwx2    0/5 nodes are available: 2 node(s) had untolerated taint(s), 3 node(s) didn't match Pod's node affinity/selector. no new claims to deallocate, preemption: 0/5 nodes are available: 5 Preemption is not helpful for scheduling.
testapp     24m         Warning   FailedScheduling       pod/nginx-testapp-5c8f4cb9d7-wjb6p    0/5 nodes are available: 2 node(s) had untolerated taint(s), 3 node(s) didn't match Pod's node affinity/selector. no new claims to deallocate, preemption: 0/5 nodes are available: 5 Preemption is not helpful for scheduling.
testapp     24m         Normal    TaintManagerEviction   pod/nginx-testapp-5c8f4cb9d7-4pl6l    Marking for deletion Pod testapp/nginx-testapp-5c8f4cb9d7-4pl6l
testapp     20m         Normal    Scheduled              pod/nginx-testapp-5c8f4cb9d7-vjwx2    Successfully assigned testapp/nginx-testapp-5c8f4cb9d7-vjwx2 to e1
testapp     20m         Normal    Scheduled              pod/nginx-testapp-5c8f4cb9d7-m5z9f    Successfully assigned testapp/nginx-testapp-5c8f4cb9d7-m5z9f to e1
testapp     20m         Normal    Scheduled              pod/nginx-testapp-5c8f4cb9d7-wjb6p    Successfully assigned testapp/nginx-testapp-5c8f4cb9d7-wjb6p to e1
testapp     107s        Normal    TaintManagerEviction   pod/nginx-testapp-5c8f4cb9d7-wjb6p    Cancelling deletion of Pod testapp/nginx-testapp-5c8f4cb9d7-wjb6p
testapp     108s        Normal    TaintManagerEviction   pod/nginx-testapp-5c8f4cb9d7-vjwx2    Cancelling deletion of Pod testapp/nginx-testapp-5c8f4cb9d7-vjwx2
testapp     107s        Normal    TaintManagerEviction   pod/nginx-testapp-5c8f4cb9d7-m5z9f    Cancelling deletion of Pod testapp/nginx-testapp-5c8f4cb9d7-m5z9f
testapp     12m         Warning   NodeNotReady           pod/nginx-testapp-5c8f4cb9d7-vjwx2    Node is not ready
testapp     115s        Warning   NodeNotReady           pod/nginx-testapp-5c8f4cb9d7-m5z9f    Node is not ready
testapp     115s        Warning   NodeNotReady           pod/nginx-testapp-5c8f4cb9d7-wjb6p    Node is not ready
testapp     7m10s       Normal    TaintManagerEviction   pod/nginx-testapp-5c8f4cb9d7-m5z9f    Marking for deletion Pod testapp/nginx-testapp-5c8f4cb9d7-m5z9f
testapp     7m10s       Warning   FailedScheduling       pod/nginx-testapp-5c8f4cb9d7-c6rrc    0/5 nodes are available: 2 node(s) had untolerated taint(s), 3 node(s) didn't match Pod's node affinity/selector. no new claims to deallocate, preemption: 0/5 nodes are available: 5 Preemption is not helpful for scheduling.
testapp     7m10s       Normal    TaintManagerEviction   pod/nginx-testapp-5c8f4cb9d7-wjb6p    Marking for deletion Pod testapp/nginx-testapp-5c8f4cb9d7-wjb6p
testapp     7m10s       Warning   FailedScheduling       pod/nginx-testapp-5c8f4cb9d7-g92hp    0/5 nodes are available: 2 node(s) had untolerated taint(s), 3 node(s) didn't match Pod's node affinity/selector. no new claims to deallocate, preemption: 0/5 nodes are available: 5 Preemption is not helpful for scheduling.
testapp     7m10s       Normal    SuccessfulCreate       replicaset/nginx-testapp-5c8f4cb9d7   Created pod: nginx-testapp-5c8f4cb9d7-g92hp
testapp     7m10s       Normal    SuccessfulCreate       replicaset/nginx-testapp-5c8f4cb9d7   Created pod: nginx-testapp-5c8f4cb9d7-c6rrc
testapp     7m10s       Warning   FailedScheduling       pod/nginx-testapp-5c8f4cb9d7-ht5wl    0/5 nodes are available: 2 node(s) had untolerated taint(s), 3 node(s) didn't match Pod's node affinity/selector. no new claims to deallocate, preemption: 0/5 nodes are available: 5 Preemption is not helpful for scheduling.
testapp     7m10s       Normal    TaintManagerEviction   pod/nginx-testapp-5c8f4cb9d7-vjwx2    Marking for deletion Pod testapp/nginx-testapp-5c8f4cb9d7-vjwx2
testapp     7m10s       Normal    SuccessfulCreate       replicaset/nginx-testapp-5c8f4cb9d7   Created pod: nginx-testapp-5c8f4cb9d7-ht5wl
testapp     2m53s       Normal    Scheduled              pod/nginx-testapp-5c8f4cb9d7-ht5wl    Successfully assigned testapp/nginx-testapp-5c8f4cb9d7-ht5wl to e1
testapp     2m53s       Normal    Scheduled              pod/nginx-testapp-5c8f4cb9d7-c6rrc    Successfully assigned testapp/nginx-testapp-5c8f4cb9d7-c6rrc to e1
testapp     2m53s       Normal    Scheduled              pod/nginx-testapp-5c8f4cb9d7-g92hp    Successfully assigned testapp/nginx-testapp-5c8f4cb9d7-g92hp to e1
testapp     105s        Normal    TaintManagerEviction   pod/nginx-testapp-5c8f4cb9d7-c6rrc    Cancelling deletion of Pod testapp/nginx-testapp-5c8f4cb9d7-c6rrc
testapp     105s        Normal    TaintManagerEviction   pod/nginx-testapp-5c8f4cb9d7-ht5wl    Cancelling deletion of Pod testapp/nginx-testapp-5c8f4cb9d7-ht5wl
testapp     105s        Normal    TaintManagerEviction   pod/nginx-testapp-5c8f4cb9d7-g92hp    Cancelling deletion of Pod testapp/nginx-testapp-5c8f4cb9d7-g92hp
