NAMESPACE   LAST SEEN   TYPE      REASON                 OBJECT                                MESSAGE
default     15m         Normal    NodeNotReady           node/e1                               Node e1 status is now: NodeNotReady
default     15m         Normal    NodeNotReady           node/e2                               Node e2 status is now: NodeNotReady
kubeedge    15m         Warning   NodeNotReady           pod/edge-eclipse-mosquitto-7l5gz      Node is not ready
kubeedge    15m         Warning   NodeNotReady           pod/edge-eclipse-mosquitto-szthb      Node is not ready
kubeedge    15m         Warning   NodeNotReady           pod/edgemesh-agent-l2n4z              Node is not ready
kubeedge    15m         Warning   NodeNotReady           pod/edgemesh-agent-qf7pk              Node is not ready
testapp     54m         Warning   NodeNotReady           pod/nginx-testapp-5c8f4cb9d7-rm27h    Node is not ready
testapp     54m         Warning   NodeNotReady           pod/nginx-testapp-5c8f4cb9d7-slx67    Node is not ready
testapp     54m         Warning   NodeNotReady           pod/nginx-testapp-5c8f4cb9d7-gggcl    Node is not ready
testapp     49m         Normal    SuccessfulCreate       replicaset/nginx-testapp-5c8f4cb9d7   Created pod: nginx-testapp-5c8f4cb9d7-lc5ff
testapp     49m         Normal    SuccessfulCreate       replicaset/nginx-testapp-5c8f4cb9d7   Created pod: nginx-testapp-5c8f4cb9d7-g7m5p
testapp     49m         Normal    TaintManagerEviction   pod/nginx-testapp-5c8f4cb9d7-slx67    Marking for deletion Pod testapp/nginx-testapp-5c8f4cb9d7-slx67
testapp     49m         Normal    TaintManagerEviction   pod/nginx-testapp-5c8f4cb9d7-rm27h    Marking for deletion Pod testapp/nginx-testapp-5c8f4cb9d7-rm27h
testapp     49m         Warning   FailedScheduling       pod/nginx-testapp-5c8f4cb9d7-g7m5p    0/5 nodes are available: 2 node(s) had untolerated taint(s), 3 node(s) didn't match Pod's node affinity/selector. no new claims to deallocate, preemption: 0/5 nodes are available: 5 Preemption is not helpful for scheduling.
testapp     49m         Warning   FailedScheduling       pod/nginx-testapp-5c8f4cb9d7-lc5ff    0/5 nodes are available: 2 node(s) had untolerated taint(s), 3 node(s) didn't match Pod's node affinity/selector. no new claims to deallocate, preemption: 0/5 nodes are available: 5 Preemption is not helpful for scheduling.
testapp     49m         Warning   FailedScheduling       pod/nginx-testapp-5c8f4cb9d7-8pl5k    0/5 nodes are available: 2 node(s) had untolerated taint(s), 3 node(s) didn't match Pod's node affinity/selector. no new claims to deallocate, preemption: 0/5 nodes are available: 5 Preemption is not helpful for scheduling.
testapp     49m         Normal    SuccessfulCreate       replicaset/nginx-testapp-5c8f4cb9d7   Created pod: nginx-testapp-5c8f4cb9d7-8pl5k
testapp     49m         Normal    TaintManagerEviction   pod/nginx-testapp-5c8f4cb9d7-gggcl    Marking for deletion Pod testapp/nginx-testapp-5c8f4cb9d7-gggcl
testapp     44m         Normal    Scheduled              pod/nginx-testapp-5c8f4cb9d7-8pl5k    Successfully assigned testapp/nginx-testapp-5c8f4cb9d7-8pl5k to e1
testapp     44m         Normal    Scheduled              pod/nginx-testapp-5c8f4cb9d7-lc5ff    Successfully assigned testapp/nginx-testapp-5c8f4cb9d7-lc5ff to e1
testapp     44m         Normal    Scheduled              pod/nginx-testapp-5c8f4cb9d7-g7m5p    Successfully assigned testapp/nginx-testapp-5c8f4cb9d7-g7m5p to e1
testapp     44m         Normal    TaintManagerEviction   pod/nginx-testapp-5c8f4cb9d7-lc5ff    Cancelling deletion of Pod testapp/nginx-testapp-5c8f4cb9d7-lc5ff
testapp     44m         Normal    TaintManagerEviction   pod/nginx-testapp-5c8f4cb9d7-g7m5p    Cancelling deletion of Pod testapp/nginx-testapp-5c8f4cb9d7-g7m5p
testapp     44m         Normal    TaintManagerEviction   pod/nginx-testapp-5c8f4cb9d7-8pl5k    Cancelling deletion of Pod testapp/nginx-testapp-5c8f4cb9d7-8pl5k
testapp     35m         Warning   NodeNotReady           pod/nginx-testapp-5c8f4cb9d7-8pl5k    Node is not ready
testapp     35m         Warning   NodeNotReady           pod/nginx-testapp-5c8f4cb9d7-lc5ff    Node is not ready
testapp     35m         Warning   NodeNotReady           pod/nginx-testapp-5c8f4cb9d7-g7m5p    Node is not ready
testapp     29m         Warning   FailedScheduling       pod/nginx-testapp-5c8f4cb9d7-h42cm    0/5 nodes are available: 2 node(s) had untolerated taint(s), 3 node(s) didn't match Pod's node affinity/selector. no new claims to deallocate, preemption: 0/5 nodes are available: 5 Preemption is not helpful for scheduling.
testapp     29m         Normal    SuccessfulCreate       replicaset/nginx-testapp-5c8f4cb9d7   Created pod: nginx-testapp-5c8f4cb9d7-6zvqz
testapp     29m         Warning   FailedScheduling       pod/nginx-testapp-5c8f4cb9d7-wntbc    0/5 nodes are available: 2 node(s) had untolerated taint(s), 3 node(s) didn't match Pod's node affinity/selector. no new claims to deallocate, preemption: 0/5 nodes are available: 5 Preemption is not helpful for scheduling.
testapp     29m         Normal    TaintManagerEviction   pod/nginx-testapp-5c8f4cb9d7-lc5ff    Marking for deletion Pod testapp/nginx-testapp-5c8f4cb9d7-lc5ff
testapp     29m         Normal    SuccessfulCreate       replicaset/nginx-testapp-5c8f4cb9d7   Created pod: nginx-testapp-5c8f4cb9d7-h42cm
testapp     29m         Normal    SuccessfulCreate       replicaset/nginx-testapp-5c8f4cb9d7   Created pod: nginx-testapp-5c8f4cb9d7-wntbc
testapp     29m         Warning   FailedScheduling       pod/nginx-testapp-5c8f4cb9d7-6zvqz    0/5 nodes are available: 2 node(s) had untolerated taint(s), 3 node(s) didn't match Pod's node affinity/selector. no new claims to deallocate, preemption: 0/5 nodes are available: 5 Preemption is not helpful for scheduling.
testapp     29m         Normal    TaintManagerEviction   pod/nginx-testapp-5c8f4cb9d7-g7m5p    Marking for deletion Pod testapp/nginx-testapp-5c8f4cb9d7-g7m5p
testapp     29m         Normal    TaintManagerEviction   pod/nginx-testapp-5c8f4cb9d7-8pl5k    Marking for deletion Pod testapp/nginx-testapp-5c8f4cb9d7-8pl5k
testapp     25m         Normal    Scheduled              pod/nginx-testapp-5c8f4cb9d7-6zvqz    Successfully assigned testapp/nginx-testapp-5c8f4cb9d7-6zvqz to e1
testapp     25m         Normal    Scheduled              pod/nginx-testapp-5c8f4cb9d7-h42cm    Successfully assigned testapp/nginx-testapp-5c8f4cb9d7-h42cm to e1
testapp     25m         Normal    Scheduled              pod/nginx-testapp-5c8f4cb9d7-wntbc    Successfully assigned testapp/nginx-testapp-5c8f4cb9d7-wntbc to e1
testapp     25m         Normal    TaintManagerEviction   pod/nginx-testapp-5c8f4cb9d7-h42cm    Cancelling deletion of Pod testapp/nginx-testapp-5c8f4cb9d7-h42cm
testapp     25m         Normal    TaintManagerEviction   pod/nginx-testapp-5c8f4cb9d7-6zvqz    Cancelling deletion of Pod testapp/nginx-testapp-5c8f4cb9d7-6zvqz
testapp     25m         Normal    TaintManagerEviction   pod/nginx-testapp-5c8f4cb9d7-wntbc    Cancelling deletion of Pod testapp/nginx-testapp-5c8f4cb9d7-wntbc
testapp     15m         Warning   NodeNotReady           pod/nginx-testapp-5c8f4cb9d7-wntbc    Node is not ready
testapp     15m         Warning   NodeNotReady           pod/nginx-testapp-5c8f4cb9d7-h42cm    Node is not ready
testapp     15m         Warning   NodeNotReady           pod/nginx-testapp-5c8f4cb9d7-6zvqz    Node is not ready
testapp     10m         Normal    TaintManagerEviction   pod/nginx-testapp-5c8f4cb9d7-6zvqz    Marking for deletion Pod testapp/nginx-testapp-5c8f4cb9d7-6zvqz
testapp     10m         Normal    SuccessfulCreate       replicaset/nginx-testapp-5c8f4cb9d7   Created pod: nginx-testapp-5c8f4cb9d7-8dq9d
testapp     10m         Warning   FailedScheduling       pod/nginx-testapp-5c8f4cb9d7-8dq9d    0/5 nodes are available: 2 node(s) had untolerated taint(s), 3 node(s) didn't match Pod's node affinity/selector. no new claims to deallocate, preemption: 0/5 nodes are available: 5 Preemption is not helpful for scheduling.
testapp     10m         Normal    SuccessfulCreate       replicaset/nginx-testapp-5c8f4cb9d7   Created pod: nginx-testapp-5c8f4cb9d7-f9bjh
testapp     10m         Warning   FailedScheduling       pod/nginx-testapp-5c8f4cb9d7-f9bjh    0/5 nodes are available: 2 node(s) had untolerated taint(s), 3 node(s) didn't match Pod's node affinity/selector. no new claims to deallocate, preemption: 0/5 nodes are available: 5 Preemption is not helpful for scheduling.
testapp     10m         Normal    TaintManagerEviction   pod/nginx-testapp-5c8f4cb9d7-wntbc    Marking for deletion Pod testapp/nginx-testapp-5c8f4cb9d7-wntbc
testapp     10m         Warning   FailedScheduling       pod/nginx-testapp-5c8f4cb9d7-rlc7z    0/5 nodes are available: 2 node(s) had untolerated taint(s), 3 node(s) didn't match Pod's node affinity/selector. no new claims to deallocate, preemption: 0/5 nodes are available: 5 Preemption is not helpful for scheduling.
testapp     10m         Normal    SuccessfulCreate       replicaset/nginx-testapp-5c8f4cb9d7   Created pod: nginx-testapp-5c8f4cb9d7-rlc7z
testapp     10m         Normal    TaintManagerEviction   pod/nginx-testapp-5c8f4cb9d7-h42cm    Marking for deletion Pod testapp/nginx-testapp-5c8f4cb9d7-h42cm
testapp     6m16s       Normal    TaintManagerEviction   pod/nginx-testapp-5c8f4cb9d7-rlc7z    Cancelling deletion of Pod testapp/nginx-testapp-5c8f4cb9d7-rlc7z
testapp     6m16s       Normal    TaintManagerEviction   pod/nginx-testapp-5c8f4cb9d7-f9bjh    Cancelling deletion of Pod testapp/nginx-testapp-5c8f4cb9d7-f9bjh
testapp     6m16s       Normal    Scheduled              pod/nginx-testapp-5c8f4cb9d7-f9bjh    Successfully assigned testapp/nginx-testapp-5c8f4cb9d7-f9bjh to e1
testapp     6m16s       Normal    TaintManagerEviction   pod/nginx-testapp-5c8f4cb9d7-8dq9d    Cancelling deletion of Pod testapp/nginx-testapp-5c8f4cb9d7-8dq9d
testapp     6m16s       Normal    Scheduled              pod/nginx-testapp-5c8f4cb9d7-rlc7z    Successfully assigned testapp/nginx-testapp-5c8f4cb9d7-rlc7z to e1
testapp     6m16s       Normal    Scheduled              pod/nginx-testapp-5c8f4cb9d7-8dq9d    Successfully assigned testapp/nginx-testapp-5c8f4cb9d7-8dq9d to e1
